Workbook

Sheet February
A10: Office of the Library Services
A11: STATISTICAL REPORT on the LIBRARY USERS Daily Breakdown - FEBRUARY 2026
A12: Bachelor of Science in Psychology
A13: FEBRUARY 2026 | C13: 1 | D13: 2 | E13: 3 | F13: 4 | G13: 5 | H13: 6 | I13: 7 | J13: 8 | K13: 9 | L13: 10 | M13: 11 | N13: 12 | O13: 13 | P13: 14 | Q13: 15 | R13: 16 | S13: 17 | T13: 18 | U13: 19 | V13: 20 | W13: 21 | X13: 22 | Y13: 23 | Z13: 24 | AA13: 25 | AB13: 26 | AC13: 27 | AD13: 28 | AE13: 29 | AF13: 30 | AG13: 31 | AH13: TOTAL
A14: Bachelor of Science in Psychology (COLLEGE OF ARTS AND SCIENCES) | B14: Number of Male Requestor | C14: 0 | D14: 0 | E14: 0 | F14: 0 | G14: 0 | H14: 0 | I14: 0 | J14: 0 | K14: 0 | L14: 0 | M14: 0 | N14: 0 | O14: 0 | P14: 0 | Q14: 0 | R14: 0 | S14: 0 | T14: 0 | U14: 0 | V14: 0 | W14: 0 | X14: 0 | Y14: 0 | Z14: 0 | AA14: 0 | AB14: 0 | AC14: 0 | AD14: 0 | AE14: 0 | AF14: 0 | AG14: 0 | AH14: =SUM(C14:AG14) -> 0
B15: Number of Female Requestor | C15: 0 | D15: 0 | E15: 0 | F15: 0 | G15: 0 | H15: 0 | I15: 0 | J15: 0 | K15: 0 | L15: 0 | M15: 0 | N15: 0 | O15: 0 | P15: 0 | Q15: 0 | R15: 0 | S15: 0 | T15: 0 | U15: 0 | V15: 0 | W15: 0 | X15: 0 | Y15: 0 | Z15: 0 | AA15: 0 | AB15: 0 | AC15: 0 | AD15: 0 | AE15: 0 | AF15: 0 | AG15: 0 | AH15: =SUM(C15:AG15) -> 0
A17: Bachelor of Arts in Communication
A18: FEBRUARY 2026 | C18: 1 | D18: 2 | E18: 3 | F18: 4 | G18: 5 | H18: 6 | I18: 7 | J18: 8 | K18: 9 | L18: 10 | M18: 11 | N18: 12 | O18: 13 | P18: 14 | Q18: 15 | R18: 16 | S18: 17 | T18: 18 | U18: 19 | V18: 20 | W18: 21 | X18: 22 | Y18: 23 | Z18: 24 | AA18: 25 | AB18: 26 | AC18: 27 | AD18: 28 | AE18: 29 | AF18: 30 | AG18: 31 | AH18: TOTAL
A19: Bachelor of Arts in Communication (COLLEGE OF ARTS AND SCIENCES) | B19: Number of Male Requestor | C19: 0 | D19: 0 | E19: 0 | F19: 0 | G19: 0 | H19: 0 | I19: 0 | J19: 0 | K19: 0 | L19: 0 | M19: 0 | N19: 0 | O19: 0 | P19: 0 | Q19: 0 | R19: 0 | S19: 0 | T19: 0 | U19: 0 | V19: 0 | W19: 0 | X19: 0 | Y19: 0 | Z19: 0 | AA19: 0 | AB19: 0 | AC19: 0 | AD19: 0 | AE19: 0 | AF19: 0 | AG19: 0 | AH19: =SUM(C19:AG19) -> 0
B20: Number of Female Requestor | C20: 0 | D20: 0 | E20: 0 | F20: 0 | G20: 0 | H20: 0 | I20: 0 | J20: 0 | K20: 0 | L20: 0 | M20: 0 | N20: 0 | O20: 0 | P20: 0 | Q20: 0 | R20: 0 | S20: 0 | T20: 0 | U20: 0 | V20: 0 | W20: 0 | X20: 0 | Y20: 0 | Z20: 0 | AA20: 0 | AB20: 0 | AC20: 0 | AD20: 0 | AE20: 0 | AF20: 0 | AG20: 0 | AH20: =SUM(C20:AG20) -> 0
A22: Bachelor of Industrial Technology Major in Electrical Technology
A23: FEBRUARY 2026 | C23: 1 | D23: 2 | E23: 3 | F23: 4 | G23: 5 | H23: 6 | I23: 7 | J23: 8 | K23: 9 | L23: 10 | M23: 11 | N23: 12 | O23: 13 | P23: 14 | Q23: 15 | R23: 16 | S23: 17 | T23: 18 | U23: 19 | V23: 20 | W23: 21 | X23: 22 | Y23: 23 | Z23: 24 | AA23: 25 | AB23: 26 | AC23: 27 | AD23: 28 | AE23: 29 | AF23: 30 | AG23: 31 | AH23: TOTAL
A24: Bachelor of Industrial Technology Major in Electrical Technology (COLLEGE OF INDUSTRIAL TECHNOLOGY) | B24: Number of Male Requestor | C24: 0 | D24: 0 | E24: 0 | F24: 0 | G24: 0 | H24: 0 | I24: 0 | J24: 0 | K24: 6 | L24: 0 | M24: 3 | N24: 4 | O24: 0 | P24: 0 | Q24: 0 | R24: 9 | S24: 0 | T24: 0 | U24: 8 | V24: 0 | W24: 0 | X24: 0 | Y24: 5 | Z24: 0 | AA24: 1 | AB24: 0 | AC24: 0 | AD24: 0 | AE24: 0 | AF24: 0 | AG24: 0 | AH24: =SUM(C24:AG24) -> 0
B25: Number of Female Requestor | C25: 0 | D25: 0 | E25: 0 | F25: 0 | G25: 0 | H25: 0 | I25: 0 | J25: 0 | K25: 0 | L25: 0 | M25: 0 | N25: 1 | O25: 0 | P25: 0 | Q25: 0 | R25: 1 | S25: 0 | T25: 0 | U25: 1 | V25: 0 | W25: 0 | X25: 0 | Y25: 0 | Z25: 0 | AA25: 0 | AB25: 0 | AC25: 0 | AD25: 0 | AE25: 0 | AF25: 0 | AG25: 0 | AH25: =SUM(C25:AG25) -> 0
A27: Bachelor of Industrial Technology Major in Computer Technology
A28: FEBRUARY 2026 | C28: 1 | D28: 2 | E28: 3 | F28: 4 | G28: 5 | H28: 6 | I28: 7 | J28: 8 | K28: 9 | L28: 10 | M28: 11 | N28: 12 | O28: 13 | P28: 14 | Q28: 15 | R28: 16 | S28: 17 | T28: 18 | U28: 19 | V28: 20 | W28: 21 | X28: 22 | Y28: 23 | Z28: 24 | AA28: 25 | AB28: 26 | AC28: 27 | AD28: 28 | AE28: 29 | AF28: 30 | AG28: 31 | AH28: TOTAL
A29: Bachelor of Industrial Technology Major in Computer Technology (COLLEGE OF INDUSTRIAL TECHNOLOGY) | B29: Number of Male Requestor | C29: 0 | D29: 0 | E29: 1 | F29: 3 | G29: 1 | H29: 1 | I29: 0 | J29: 0 | K29: 5 | L29: 0 | M29: 0 | N29: 1 | O29: 4 | P29: 0 | Q29: 0 | R29: 0 | S29: 0 | T29: 0 | U29: 3 | V29: 0 | W29: 0 | X29: 0 | Y29: 5 | Z29: 1 | AA29: 2 | AB29: 1 | AC29: 0 | AD29: 0 | AE29: 0 | AF29: 0 | AG29: 0 | AH29: =SUM(C29:AG29) -> 0
B30: Number of Female Requestor | C30: 0 | D30: 0 | E30: 2 | F30: 5 | G30: 4 | H30: 0 | I30: 0 | J30: 0 | K30: 2 | L30: 0 | M30: 0 | N30: 2 | O30: 3 | P30: 0 | Q30: 0 | R30: 0 | S30: 0 | T30: 3 | U30: 2 | V30: 0 | W30: 0 | X30: 0 | Y30: 2 | Z30: 0 | AA30: 1 | AB30: 0 | AC30: 0 | AD30: 0 | AE30: 0 | AF30: 0 | AG30: 0 | AH30: =SUM(C30:AG30) -> 0
A32: Bachelor of Industrial Technology Major in Instrumentation & Communication Technology
A33: FEBRUARY 2026 | C33: 1 | D33: 2 | E33: 3 | F33: 4 | G33: 5 | H33: 6 | I33: 7 | J33: 8 | K33: 9 | L33: 10 | M33: 11 | N33: 12 | O33: 13 | P33: 14 | Q33: 15 | R33: 16 | S33: 17 | T33: 18 | U33: 19 | V33: 20 | W33: 21 | X33: 22 | Y33: 23 | Z33: 24 | AA33: 25 | AB33: 26 | AC33: 27 | AD33: 28 | AE33: 29 | AF33: 30 | AG33: 31 | AH33: TOTAL
A34: Bachelor of Industrial Technology Major in Instrumentation & Communication Technology (COLLEGE OF INDUSTRIAL TECHNOLOGY) | B34: Number of Male Requestor | C34: 0 | D34: 0 | E34: 2 | F34: 0 | G34: 0 | H34: 0 | I34: 0 | J34: 0 | K34: 0 | L34: 1 | M34: 0 | N34: 0 | O34: 0 | P34: 0 | Q34: 0 | R34: 2 | S34: 0 | T34: 0 | U34: 0 | V34: 0 | W34: 0 | X34: 0 | Y34: 0 | Z34: 1 | AA34: 0 | AB34: 0 | AC34: 0 | AD34: 0 | AE34: 0 | AF34: 0 | AG34: 0 | AH34: =SUM(C34:AG34) -> 0
B35: Number of Female Requestor | C35: 0 | D35: 0 | E35: 1 | F35: 0 | G35: 0 | H35: 0 | I35: 0 | J35: 0 | K35: 0 | L35: 0 | M35: 0 | N35: 0 | O35: 0 | P35: 0 | Q35: 0 | R35: 0 | S35: 0 | T35: 0 | U35: 0 | V35: 0 | W35: 0 | X35: 0 | Y35: 0 | Z35: 2 | AA35: 0 | AB35: 0 | AC35: 0 | AD35: 0 | AE35: 0 | AF35: 0 | AG35: 0 | AH35: =SUM(C35:AG35) -> 0
A37: Bachelor of Industrial Technology Major in Electronics Technology
A38: FEBRUARY 2026 | C38: 1 | D38: 2 | E38: 3 | F38: 4 | G38: 5 | H38: 6 | I38: 7 | J38: 8 | K38: 9 | L38: 10 | M38: 11 | N38: 12 | O38: 13 | P38: 14 | Q38: 15 | R38: 16 | S38: 17 | T38: 18 | U38: 19 | V38: 20 | W38: 21 | X38: 22 | Y38: 23 | Z38: 24 | AA38: 25 | AB38: 26 | AC38: 27 | AD38: 28 | AE38: 29 | AF38: 30 | AG38: 31 | AH38: TOTAL
A39: Bachelor of Industrial Technology Major in Electronics Technology (COLLEGE OF INDUSTRIAL TECHNOLOGY) | B39: Number of Male Requestor | C39: 0 | D39: 2 | E39: 1 | F39: 0 | G39: 0 | H39: 0 | I39: 0 | J39: 0 | K39: 4 | L39: 0 | M39: 0 | N39: 0 | O39: 1 | P39: 0 | Q39: 0 | R39: 2 | S39: 0 | T39: 3 | U39: 3 | V39: 0 | W39: 0 | X39: 0 | Y39: 6 | Z39: 1 | AA39: 0 | AB39: 0 | AC39: 0 | AD39: 0 | AE39: 0 | AF39: 0 | AG39: 0 | AH39: =SUM(C39:AG39) -> 0
B40: Number of Female Requestor | C40: 0 | D40: 0 | E40: 2 | F40: 0 | G40: 0 | H40: 0 | I40: 0 | J40: 0 | K40: 4 | L40: 0 | M40: 0 | N40: 0 | O40: 1 | P40: 0 | Q40: 0 | R40: 4 | S40: 0 | T40: 0 | U40: 2 | V40: 0 | W40: 0 | X40: 0 | Y40: 2 | Z40: 1 | AA40: 0 | AB40: 0 | AC40: 0 | AD40: 0 | AE40: 0 | AF40: 0 | AG40: 0 | AH40: =SUM(C40:AG40) -> 0
A42: Bachelor of Science in Information Technology - Business Analytics Track
A43: FEBRUARY 2026 | C43: 1 | D43: 2 | E43: 3 | F43: 4 | G43: 5 | H43: 6 | I43: 7 | J43: 8 | K43: 9 | L43: 10 | M43: 11 | N43: 12 | O43: 13 | P43: 14 | Q43: 15 | R43: 16 | S43: 17 | T43: 18 | U43: 19 | V43: 20 | W43: 21 | X43: 22 | Y43: 23 | Z43: 24 | AA43: 25 | AB43: 26 | AC43: 27 | AD43: 28 | AE43: 29 | AF43: 30 | AG43: 31 | AH43: TOTAL
A44: Bachelor of Science in Information Technology (COLLEGE OF INFORMATICS AND COMPUTING SCIENCES) | B44: Number of Male Requestor | C44: 0 | D44: 6 | E44: 1 | F44: 4 | G44: 3 | H44: 2 | I44: 0 | J44: 0 | K44: 1 | L44: 8 | M44: 7 | N44: 13 | O44: 2 | P44: 0 | Q44: 0 | R44: 1 | S44: 0 | T44: 4 | U44: 1 | V44: 0 | W44: 0 | X44: 0 | Y44: 17 | Z44: 4 | AA44: 0 | AB44: 8 | AC44: 4 | AD44: 1 | AE44: 0 | AF44: 0 | AG44: 0 | AH44: =SUM(C44:AG44) -> 0
B45: Number of Female Requestor | C45: 0 | D45: 2 | E45: 0 | F45: 3 | G45: 4 | H45: 1 | I45: 0 | J45: 0 | K45: 0 | L45: 9 | M45: 0 | N45: 4 | O45: 3 | P45: 0 | Q45: 0 | R45: 0 | S45: 0 | T45: 1 | U45: 3 | V45: 0 | W45: 6 | X45: 0 | Y45: 6 | Z45: 1 | AA45: 0 | AB45: 0 | AC45: 0 | AD45: 4 | AE45: 0 | AF45: 0 | AG45: 0 | AH45: =SUM(C45:AG45) -> 0
A47: Bachelor of Science in Information Technology - Service Management Track
A48: FEBRUARY 2026 | C48: 1 | D48: 2 | E48: 3 | F48: 4 | G48: 5 | H48: 6 | I48: 7 | J48: 8 | K48: 9 | L48: 10 | M48: 11 | N48: 12 | O48: 13 | P48: 14 | Q48: 15 | R48: 16 | S48: 17 | T48: 18 | U48: 19 | V48: 20 | W48: 21 | X48: 22 | Y48: 23 | Z48: 24 | AA48: 25 | AB48: 26 | AC48: 27 | AD48: 28 | AE48: 29 | AF48: 30 | AG48: 31 | AH48: TOTAL
A49: Bachelor of Science in Information Technology (COLLEGE OF INFORMATICS AND COMPUTING SCIENCES) | B49: Number of Male Requestor | C49: 0 | D49: 5 | E49: 0 | F49: 2 | G49: 1 | H49: 1 | I49: 0 | J49: 0 | K49: 2 | L49: 7 | M49: 1 | N49: 2 | O49: 2 | P49: 0 | Q49: 0 | R49: 4 | S49: 0 | T49: 1 | U49: 1 | V49: 0 | W49: 0 | X49: 0 | Y49: 16 | Z49: 4 | AA49: 0 | AB49: 3 | AC49: 0 | AD49: 0 | AE49: 0 | AF49: 0 | AG49: 0 | AH49: =SUM(C49:AG49) -> 0
B50: Number of Female Requestor | C50: 0 | D50: 1 | E50: 0 | F50: 0 | G50: 2 | H50: 0 | I50: 0 | J50: 0 | K50: 0 | L50: 6 | M50: 0 | N50: 2 | O50: 1 | P50: 0 | Q50: 0 | R50: 3 | S50: 0 | T50: 1 | U50: 2 | V50: 0 | W50: 0 | X50: 0 | Y50: 5 | Z50: 1 | AA50: 0 | AB50: 0 | AC50: 0 | AD50: 0 | AE50: 0 | AF50: 0 | AG50: 0 | AH50: =SUM(C50:AG50) -> 0
A52: Bachelor of Science in Information Technology - Network Technology Track
A53: FEBRUARY 2026 | C53: 1 | D53: 2 | E53: 3 | F53: 4 | G53: 5 | H53: 6 | I53: 7 | J53: 8 | K53: 9 | L53: 10 | M53: 11 | N53: 12 | O53: 13 | P53: 14 | Q53: 15 | R53: 16 | S53: 17 | T53: 18 | U53: 19 | V53: 20 | W53: 21 | X53: 22 | Y53: 23 | Z53: 24 | AA53: 25 | AB53: 26 | AC53: 27 | AD53: 28 | AE53: 29 | AF53: 30 | AG53: 31 | AH53: TOTAL
A54: Bachelor of Science in Information Technology (COLLEGE OF INFORMATICS AND COMPUTING SCIENCES) | B54: Number of Male Requestor | C54: 0 | D54: 4 | E54: 1 | F54: 8 | G54: 3 | H54: 3 | I54: 0 | J54: 0 | K54: 0 | L54: 6 | M54: 0 | N54: 1 | O54: 0 | P54: 0 | Q54: 0 | R54: 1 | S54: 0 | T54: 3 | U54: 2 | V54: 0 | W54: 0 | X54: 0 | Y54: 17 | Z54: 4 | AA54: 1 | AB54: 2 | AC54: 0 | AD54: 0 | AE54: 0 | AF54: 0 | AG54: 0 | AH54: =SUM(C54:AG54) -> 0
B55: Number of Female Requestor | C55: 0 | D55: 0 | E55: 7 | F55: 9 | G55: 2 | H55: 0 | I55: 0 | J55: 0 | K55: 0 | L55: 6 | M55: 1 | N55: 2 | O55: 0 | P55: 0 | Q55: 0 | R55: 0 | S55: 0 | T55: 0 | U55: 2 | V55: 0 | W55: 0 | X55: 0 | Y55: 5 | Z55: 0 | AA55: 1 | AB55: 0 | AC55: 0 | AD55: 0 | AE55: 0 | AF55: 0 | AG55: 0 | AH55: =SUM(C55:AG55) -> 0
A57: Bachelor of Science in Business Administration Major in Human Resource Management
A58: FEBRUARY 2026 | C58: 1 | D58: 2 | E58: 3 | F58: 4 | G58: 5 | H58: 6 | I58: 7 | J58: 8 | K58: 9 | L58: 10 | M58: 11 | N58: 12 | O58: 13 | P58: 14 | Q58: 15 | R58: 16 | S58: 17 | T58: 18 | U58: 19 | V58: 20 | W58: 21 | X58: 22 | Y58: 23 | Z58: 24 | AA58: 25 | AB58: 26 | AC58: 27 | AD58: 28 | AE58: 29 | AF58: 30 | AG58: 31 | AH58: TOTAL
...

Sheet Detailed stat
A1: Republic of the Philippines
A2: BATANGAS STATE UNIVERSITY
A3: The National Engineering University
A4: Lipa Campus
A5: A Tanco Drive, Brgy. Marawoy Lipa City, Batangas, Philippines 4217
A6: Tel Nos.: (+63 43) 980-0385; 980-0387; 980-0392 to 94 loc. 3110
A7: E-mail Address: library.lipa@g.batstate-u.edu.ph | Website Address: http://www.library.batstate-u.edu.ph
A8: Office of the Library Services
A10: LIBRARY USERS FOR THE MONTH OF FEBRUARY 2026
A12: College/Department/Office | B12: 1 | C12: 2 | D12: 3 | E12: 4 | F12: 5 | G12: 6 | H12: 7 | I12: 8 | J12: 9 | K12: 10 | L12: 11 | M12: 12 | N12: 13 | O12: 14 | P12: 15 | Q12: 16 | R12: 17 | S12: 18 | T12: 19 | U12: 20 | V12: 21 | W12: 22 | X12: 23 | Y12: 24 | Z12: 25 | AA12: 26 | AB12: 27 | AC12: 28 | AD12: 29 | AE12: 30 | AF12: 31 | AG12: Subtotal | AI12: Dept | AJ12: Course | AM12: Male | AN12: Female | AO12: Total No. of User | AP12: Total per Dept.
A13: CET | B13: =SUM(February!C24,February!C25,February!C29,February!C30,February!C34,February!C35,February!C39,February!C40) -> 0 | C13: =SUM(February!D24,February!D25,February!D29,February!D30,February!D34,February!D35,February!D39,February!D40) -> 0 | D13: =SUM(February!E24,February!E25,February!E29,February!E30,February!E34,February!E35,February!E39,February!E40) -> 0 | E13: =SUM(February!F24,February!F25,February!F29,February!F30,February!F34,February!F35,February!F39,February!F40) -> 0 | F13: =SUM(February!G24,February!G25,February!G29,February!G30,February!G34,February!G35,February!G39,February!G40) -> 0 | G13: =SUM(February!H24,February!H25,February!H29,February!H30,February!H34,February!H35,February!H39,February!H40) -> 0 | H13: =SUM(February!I24,February!I25,February!I29,February!I30,February!I34,February!I35,February!I39,February!I40) -> 0 | I13: =SUM(February!J24,February!J25,February!J29,February!J30,February!J34,February!J35,February!J39,February!J40) -> 0 | ... AF13: =SUM(February!AG24,February!AG25,February!AG29,February!AG30,February!AG34,February!AG35,February!AG39,February!AG40) -> 0 | AG13: =SUM(B13:AF13) -> 0 | AI13: C A S | AJ13: BS PSY | AM13: =SUM(February!AH14) -> 0 | AN13: =SUM(February!AH15) -> 0 | AO13: =SUM(February!AH14,February!AH15) -> 0 | AP13: =SUM(AO13,AO14) -> 0
A14: CAS | B14: =SUM(February!C14,February!C15,February!C19,February!C20) -> 0 | C14: =SUM(February!D14,February!D15,February!D19,February!D20) -> 0 | D14: =SUM(February!E14,February!E15,February!E19,February!E20) -> 0 | E14: =SUM(February!F14,February!F15,February!F19,February!F20) -> 0 | F14: =SUM(February!G14,February!G15,February!G19,February!G20) -> 0 | G14: =SUM(February!H14,February!H15,February!H19,February!H20) -> 0 | H14: =SUM(February!I14,February!I15,February!I19,February!I20) -> 0 | I14: =SUM(February!J14,February!J15,February!J19,February!J20) -> 0 | ... AF14: =SUM(February!AG14,February!AG15,February!AG19,February!AG20) -> 0 | AG14: =SUM(B14:AF14) -> 0 | AJ14: BA COMM | AM14: =SUM(February!AH19) -> 0 | AN14: =SUM(February!AH20) -> 0 | AO14: =SUM(February!AH19,February!AH20) -> 0
A15: CICS | B15: =SUM(February!C44,February!C45,February!C49,February!C50,February!C54,February!C55) -> 0 | C15: =SUM(February!D44,February!D45,February!D49,February!D50,February!D54,February!D55) -> 0 | D15: =SUM(February!E44,February!E45,February!E49,February!E50,February!E54,February!E55) -> 0 | E15: =SUM(February!F44,February!F45,February!F49,February!F50,February!F54,February!F55) -> 0 | F15: =SUM(February!G44,February!G45,February!G49,February!G50,February!G54,February!G55) -> 0 | G15: =SUM(February!H44,February!H45,February!H49,February!H50,February!H54,February!H55) -> 0 | H15: =SUM(February!I44,February!I45,February!I49,February!I50,February!I54,February!I55) -> 0 | I15: =SUM(February!J44,February!J45,February!J49,February!J50,February!J54,February!J55) -> 0 | ... AF15: =SUM(February!AG44,February!AG45,February!AG49,February!AG50,February!AG54,February!AG55) -> 0 | AG15: =SUM(B15:AF15) -> 0 | AI15: C E T | AJ15: BIT ELT | AM15: =SUM(February!AH24) -> 0 | AN15: =SUM(February!AH25) -> 0 | AO15: =SUM(February!AH24,February!AH25) -> 0 | AP15: =SUM(AO15,AO16,AO17,AO18) -> 0
A16: CABE | B16: =SUM(February!C59,February!C60,February!C64,February!C65,February!C69,February!C70,February!C74,February!C75,February!C79,February!C80) -> 0 | C16: =SUM(February!D59,February!D60,February!D64,February!D65,February!D69,February!D70,February!D74,February!D75,February!D79,February!D80) -> 0 | D16: =SUM(February!E59,February!E60,February!E64,February!E65,February!E69,February!E70,February!E74,February!E75,February!E79,February!E80) -> 0 | E16: =SUM(February!F59,February!F60,February!F64,February!F65,February!F69,February!F70,February!F74,February!F75,February!F79,February!F80) -> 0 | F16: =SUM(February!G59,February!G60,February!G64,February!G65,February!G69,February!G70,February!G74,February!G75,February!G79,February!G80) -> 0 | G16: =SUM(February!H59,February!H60,February!H64,February!H65,February!H69,February!H70,February!H74,February!H75,February!H79,February!H80) -> 0 | H16: =SUM(February!I59,February!I60,February!I64,February!I65,February!I69,February!I70,February!I74,February!I75,February!I79,February!I80) -> 0 | I16: =SUM(February!J59,February!J60,February!J64,February!J65,February!J69,February!J70,February!J74,February!J75,February!J79,February!J80) -> 0 | ... AF16: =SUM(February!AG59,February!AG60,February!AG64,February!AG65,February!AG69,February!AG70,February!AG74,February!AG75,February!AG79,February!AG80) -> 0 | AG16: =SUM(B16:AF16) -> 0 | AJ16: BIT CPT | AM16: =SUM(February!AH29) -> 0 | AN16: =SUM(February!AH30) -> 0 | AO16: =SUM(February!AH29,February!AH30) -> 0
A17: CTE | B17: =SUM(February!C84,February!C85,February!C89,February!C90,February!C94,February!C95) -> 0 | C17: =SUM(February!D84,February!D85,February!D89,February!D90,February!D94,February!D95) -> 0 | D17: =SUM(February!E84,February!E85,February!E89,February!E90,February!E94,February!E95) -> 0 | E17: =SUM(February!F84,February!F85,February!F89,February!F90,February!F94,February!F95) -> 0 | F17: =SUM(February!G84,February!G85,February!G89,February!G90,February!G94,February!G95) -> 0 | G17: =SUM(February!H84,February!H85,February!H89,February!H90,February!H94,February!H95) -> 0 | H17: =SUM(February!I84,February!I85,February!I89,February!I90,February!I94,February!I95) -> 0 | I17: =SUM(February!J84,February!J85,February!J89,February!J90,February!J94,February!J95) -> 0 | ... AF17: =SUM(February!AG84,February!AG85,February!AG89,February!AG90,February!AG94,February!AG95) -> 0 | AG17: =SUM(B17:AF17) -> 0 | AJ17: BIT I&C | AM17: =SUM(February!AH34) -> 0 | AN17: =SUM(February!AH35) -> 0 | AO17: =SUM(February!AH34,February!AH35) -> 0
A18: FACULTY / NON-TEACHING PERSONNEL | B18: =SUM(February!C100,February!C101) -> 0 | C18: =SUM(February!D100,February!D101) -> 0 | D18: =SUM(February!E100,February!E101) -> 0 | E18: =SUM(February!F100,February!F101) -> 0 | F18: =SUM(February!G100,February!G101) -> 0 | G18: =SUM(February!H100,February!H101) -> 0 | H18: =SUM(February!I100,February!I101) -> 0 | I18: =SUM(February!J100,February!J101) -> 0 | ... AF18: =SUM(February!AG100,February!AG101) -> 0 | AG18: =SUM(B18:AF18) -> 0 | AJ18: BIT ELX | AM18: =SUM(February!AH39) -> 0 | AN18: =SUM(February!AH40) -> 0 | AO18: =SUM(February!AH39,February!AH40) -> 0
A19: OUTSIDE RESEARCHERS | B19: =SUM(February!C105,February!C106) -> 0 | C19: =SUM(February!D105,February!D106) -> 0 | D19: =SUM(February!E105,February!E106) -> 0 | E19: =SUM(February!F105,February!F106) -> 0 | F19: =SUM(February!G105,February!G106) -> 0 | G19: =SUM(February!H105,February!H106) -> 0 | H19: =SUM(February!I105,February!I106) -> 0 | I19: =SUM(February!J105,February!J106) -> 0 | ... AF19: =SUM(February!AG105,February!AG106) -> 0 | AG19: =SUM(B19:AF19) -> 0 | AI19: C I C S | AJ19: BSIT BA | AM19: =SUM(February!AH44) -> 0 | AN19: =SUM(February!AH45) -> 0 | AO19: =SUM(February!AH44,February!AH45) -> 0 | AP19: =SUM(AO19,AO20,AO21) -> 0
A20: OVERALL TOTAL: | B20: =SUM(B13:B19) -> 0 | C20: =SUM(C13:C19) -> 0 | D20: =SUM(D13:D19) -> 0 | E20: =SUM(E13:E19) -> 0 | F20: =SUM(F13:F19) -> 0 | G20: =SUM(G13:G19) -> 0 | H20: =SUM(H13:H19) -> 0 | I20: =SUM(I13:I19) -> 0 | ... AF20: =SUM(AF13:AF19) -> 0 | AG20: =SUM(B20:AF20) -> 0 | AJ20: BSIT SM | AM20: =SUM(February!AH49) -> 0 | AN20: =SUM(February!AH50) -> 0 | AO20: =SUM(February!AH49,February!AH50) -> 0
AJ21: BSIT NT | AM21: =SUM(February!AH54) -> 0 | AN21: =SUM(February!AH55) -> 0 | AO21: =SUM(February!AH54,February!AH55) -> 0
A22: Prepared by: | AI22: C A B E | AJ22: BSBA HRM | AM22: =SUM(February!AH59) -> 0 | AN22: =SUM(February!AH60) -> 0 | AO22: =SUM(February!AH59,February!AH60) -> 0 | AP22: =SUM(AO22,AO23,AO24,AO25,AO26) -> 0
AJ23: BSBA OM | AM23: =SUM(February!AH64) -> 0 | AN23: =SUM(February!AH65) -> 0 | AO23: =SUM(February!AH64,February!AH65) -> 0
A24: DONALIN C. TRINIDAD, RL | AJ24: BSBA MM | AM24: =SUM(February!AH69) -> 0 | AN24: =SUM(February!AH70) -> 0 | AO24: =SUM(February!AH69,February!AH70) -> 0
A25: Administrative Aide VI Date: | AJ25: BS MA | AM25: =SUM(February!AH74) -> 0 | AN25: =SUM(February!AH75) -> 0 | AO25: =SUM(February!AH74,February!AH75) -> 0
AJ26: BS PA | AM26: =SUM(February!AH79) -> 0 | AN26: =SUM(February!AH80) -> 0 | AO26: =SUM(February!AH79,February!AH80) -> 0
A27: Reviewed by: | AI27: C T E | AJ27: BSED Mathematics | AM27: =SUM(February!AH84) -> 0 | AN27: =SUM(February!AH85) -> 0 | AO27: =SUM(February!AH84,February!AH85) -> 0 | AP27: =SUM(AO27,AO28,AO29) -> 0
AJ28: BSED Science | AM28: =SUM(February!AH89) -> 0 | AN28: =SUM(February!AH90) -> 0 | AO28: =SUM(February!AH89,February!AH90) -> 0
A29: CARLO M. PASTRANA, RL, MLIS | AJ29: BSED English | AM29: =SUM(February!AH94) -> 0 | AN29: =SUM(February!AH95) -> 0 | AO29: =SUM(February!AH94,February!AH95) -> 0
A30: College Librarian I Date: | AI30: O T H E R S | AJ30: Faculty / Non-Teaching Personnel | AM30: =SUM(February!AH100) -> 0 | AN30: =SUM(February!AH101) -> 0 | AO30: =SUM(February!AH100,February!AH101) -> 0 | AP30: =SUM(AO30,AO31) -> 0
AJ31: Outside Researchers | AM31: =SUM(February!AH105) -> 0 | AN31: =SUM(February!AH106) -> 0 | AO31: =SUM(February!AH105,February!AH106) -> 0
A32: Certified Correct: | AJ32: TOTAL | AM32: =SUM(AM13:AM31) -> 0 | AN32: =SUM(AN13:AN31) -> 0 | AO32: =SUM(AO13:AO31) -> 0
A34: ENGR. JONNAH R. MELO | AI34: SUMMARY
A35: Head, Library Services Date: | AI35: Number of Male Requestor | AM35: =SUM(February!AH14,February!AH19,February!AH24,February!AH29,February!AH34,February!AH39,February!AH44,February!AH49,February!AH54,February!AH59,February!AH64,February!AH69,February!AH74,February!AH79,February!AH84,February!AH89,February!AH94,February!AH100,February!AH105) -> 0 | AN35: =SUM(AM35,AM36) -> 0
AI36: Number of Female Requestor | AM36: =SUM(February!AH15,February!AH20,February!AH25,February!AH30,February!AH35,February!AH40,February!AH45,February!AH50,February!AH55,February!AH60,February!AH65,February!AH70,February!AH75,February!AH80,February!AH85,February!AH90,February!AH95,February!AH101,February!AH106) -> 0
